[2025-10-05T05:09:57.464+0000] {local_task_job_runner.py:120} INFO - ::group::Pre task execution logs
[2025-10-05T05:09:57.879+0000] {taskinstance.py:2076} INFO - Dependencies all met for dep_context=non-requeueable deps ti=<TaskInstance: retail_hourly_etl.retail_transactions_scd scheduled__2025-10-05T04:00:00+00:00 [queued]>
[2025-10-05T05:09:57.913+0000] {taskinstance.py:2076} INFO - Dependencies all met for dep_context=requeueable deps ti=<TaskInstance: retail_hourly_etl.retail_transactions_scd scheduled__2025-10-05T04:00:00+00:00 [queued]>
[2025-10-05T05:09:57.915+0000] {taskinstance.py:2306} INFO - Starting attempt 1 of 1
[2025-10-05T05:09:57.979+0000] {taskinstance.py:2330} INFO - Executing <Task(BashOperator): retail_transactions_scd> on 2025-10-05 04:00:00+00:00
[2025-10-05T05:09:58.111+0000] {logging_mixin.py:188} WARNING - /home/***/.local/lib/python3.12/site-packages/***/task/task_runner/standard_task_runner.py:62 DeprecationWarning: This process (pid=204) is multi-threaded, use of fork() may lead to deadlocks in the child.
[2025-10-05T05:09:58.123+0000] {standard_task_runner.py:64} INFO - Started process 214 to run task
[2025-10-05T05:09:58.097+0000] {standard_task_runner.py:90} INFO - Running: ['***', 'tasks', 'run', 'retail_hourly_etl', 'retail_transactions_scd', 'scheduled__2025-10-05T04:00:00+00:00', '--job-id', '49', '--raw', '--subdir', 'DAGS_FOLDER/retail_hourly_etl.py', '--cfg-path', '/tmp/tmpbrvh1egn']
[2025-10-05T05:09:58.129+0000] {standard_task_runner.py:91} INFO - Job 49: Subtask retail_transactions_scd
[2025-10-05T05:09:58.557+0000] {task_command.py:426} INFO - Running <TaskInstance: retail_hourly_etl.retail_transactions_scd scheduled__2025-10-05T04:00:00+00:00 [running]> on host 4be1e35054da
[2025-10-05T05:09:59.097+0000] {taskinstance.py:2648} INFO - Exporting env vars: AIRFLOW_CTX_DAG_OWNER='***' AIRFLOW_CTX_DAG_ID='retail_hourly_etl' AIRFLOW_CTX_TASK_ID='retail_transactions_scd' AIRFLOW_CTX_EXECUTION_DATE='2025-10-05T04:00:00+00:00' AIRFLOW_CTX_TRY_NUMBER='1' AIRFLOW_CTX_DAG_RUN_ID='scheduled__2025-10-05T04:00:00+00:00'
[2025-10-05T05:09:59.106+0000] {taskinstance.py:430} INFO - ::endgroup::
[2025-10-05T05:09:59.224+0000] {subprocess.py:63} INFO - Tmp dir root location: /tmp
[2025-10-05T05:09:59.230+0000] {subprocess.py:75} INFO - Running command: ['/usr/bin/bash', '-c', 'python /opt/***/public/retail_transactions_scd.py || exit 3']
[2025-10-05T05:09:59.290+0000] {subprocess.py:86} INFO - Output:
[2025-10-05T05:10:26.288+0000] {subprocess.py:93} INFO - 2025-10-05 05:10:26,287 - INFO - Running DBT command: run --select tag:retail_transactions_scd --target prod --project-dir /opt/***/dbt --profiles-dir /opt/***/dbt
[2025-10-05T05:10:27.355+0000] {subprocess.py:93} INFO - [0m05:10:27  Running with dbt=1.8.9
[2025-10-05T05:10:39.409+0000] {subprocess.py:93} INFO - [0m05:10:39  Registered adapter: postgres=1.8.2
[2025-10-05T05:10:45.224+0000] {subprocess.py:93} INFO - [0m05:10:45  Unable to do partial parsing because of a version mismatch
[2025-10-05T05:11:00.523+0000] {subprocess.py:93} INFO - [0m05:11:00  [[33mWARNING[0m]: Configuration paths exist in your dbt_project.yml file which do not apply to any resources.
[2025-10-05T05:11:00.525+0000] {subprocess.py:93} INFO - There are 1 unused configuration paths:
[2025-10-05T05:11:00.539+0000] {subprocess.py:93} INFO - - models.lionparcel_dwh.staging
[2025-10-05T05:11:01.867+0000] {subprocess.py:93} INFO - [0m05:11:01  Found 3 models, 1 source, 433 macros
[2025-10-05T05:11:01.884+0000] {subprocess.py:93} INFO - [0m05:11:01
[2025-10-05T05:11:02.583+0000] {subprocess.py:93} INFO - [0m05:11:02
[2025-10-05T05:11:02.594+0000] {subprocess.py:93} INFO - [0m05:11:02  Finished running  in 0 hours 0 minutes and 0.69 seconds (0.69s).
[2025-10-05T05:11:02.613+0000] {subprocess.py:93} INFO - [0m05:11:02  Encountered an error:
[2025-10-05T05:11:02.616+0000] {subprocess.py:93} INFO - Database Error
[2025-10-05T05:11:02.620+0000] {subprocess.py:93} INFO -   connection to server at "localhost" (::1), port 5432 failed: Connection refused
[2025-10-05T05:11:02.623+0000] {subprocess.py:93} INFO -   	Is the server running on that host and accepting TCP/IP connections?
[2025-10-05T05:11:02.624+0000] {subprocess.py:93} INFO -   connection to server at "localhost" (127.0.0.1), port 5432 failed: Connection refused
[2025-10-05T05:11:02.626+0000] {subprocess.py:93} INFO -   	Is the server running on that host and accepting TCP/IP connections?
[2025-10-05T05:11:02.628+0000] {subprocess.py:93} INFO - 
[2025-10-05T05:11:08.451+0000] {subprocess.py:97} INFO - Command exited with return code 3
[2025-10-05T05:11:08.472+0000] {taskinstance.py:441} INFO - ::group::Post task execution logs
[2025-10-05T05:11:08.699+0000] {taskinstance.py:2905} ERROR - Task failed with exception
Traceback (most recent call last):
  File "/home/airflow/.local/lib/python3.12/site-packages/airflow/models/taskinstance.py", line 465, in _execute_task
    result = _execute_callable(context=context, **execute_callable_kwargs)
             ^^^^^^^^^^^^^^^^^^^^^^^^^^^^^^^^^^^^^^^^^^^^^^^^^^^^^^^^^^^^^
  File "/home/airflow/.local/lib/python3.12/site-packages/airflow/models/taskinstance.py", line 432, in _execute_callable
    return execute_callable(context=context, **execute_callable_kwargs)
           ^^^^^^^^^^^^^^^^^^^^^^^^^^^^^^^^^^^^^^^^^^^^^^^^^^^^^^^^^^^^
  File "/home/airflow/.local/lib/python3.12/site-packages/airflow/models/baseoperator.py", line 401, in wrapper
    return func(self, *args, **kwargs)
           ^^^^^^^^^^^^^^^^^^^^^^^^^^^
  File "/home/airflow/.local/lib/python3.12/site-packages/airflow/operators/bash.py", line 243, in execute
    raise AirflowException(
airflow.exceptions.AirflowException: Bash command failed. The command returned a non-zero exit code 3.
[2025-10-05T05:11:08.812+0000] {taskinstance.py:1206} INFO - Marking task as FAILED. dag_id=retail_hourly_etl, task_id=retail_transactions_scd, run_id=scheduled__2025-10-05T04:00:00+00:00, execution_date=20251005T040000, start_date=20251005T050957, end_date=20251005T051108
[2025-10-05T05:11:09.024+0000] {standard_task_runner.py:110} ERROR - Failed to execute job 49 for task retail_transactions_scd (Bash command failed. The command returned a non-zero exit code 3.; 214)
[2025-10-05T05:11:09.203+0000] {local_task_job_runner.py:243} INFO - Task exited with return code 1
[2025-10-05T05:11:09.404+0000] {taskinstance.py:3503} INFO - 0 downstream tasks scheduled from follow-on schedule check
[2025-10-05T05:11:09.412+0000] {local_task_job_runner.py:222} INFO - ::endgroup::
