[2025-10-04T13:45:30.944+0000] {local_task_job_runner.py:120} INFO - ::group::Pre task execution logs
[2025-10-04T13:45:31.287+0000] {taskinstance.py:2076} INFO - Dependencies all met for dep_context=non-requeueable deps ti=<TaskInstance: retail_hourly_etl.source_transaction_lion_parcel manual__2025-10-04T13:45:27.569105+00:00 [queued]>
[2025-10-04T13:45:31.306+0000] {taskinstance.py:2076} INFO - Dependencies all met for dep_context=requeueable deps ti=<TaskInstance: retail_hourly_etl.source_transaction_lion_parcel manual__2025-10-04T13:45:27.569105+00:00 [queued]>
[2025-10-04T13:45:31.308+0000] {taskinstance.py:2306} INFO - Starting attempt 1 of 1
[2025-10-04T13:45:31.346+0000] {taskinstance.py:2330} INFO - Executing <Task(BashOperator): source_transaction_lion_parcel> on 2025-10-04 13:45:27.569105+00:00
[2025-10-04T13:45:31.364+0000] {standard_task_runner.py:90} INFO - Running: ['***', 'tasks', 'run', 'retail_hourly_etl', 'source_transaction_lion_parcel', 'manual__2025-10-04T13:45:27.569105+00:00', '--job-id', '14', '--raw', '--subdir', 'DAGS_FOLDER/retail_hourly_etl.py', '--cfg-path', '/tmp/tmpa73weycb']
[2025-10-04T13:45:31.368+0000] {standard_task_runner.py:91} INFO - Job 14: Subtask source_transaction_lion_parcel
[2025-10-04T13:45:31.372+0000] {logging_mixin.py:188} WARNING - /home/***/.local/lib/python3.12/site-packages/***/task/task_runner/standard_task_runner.py:62 DeprecationWarning: This process (pid=195) is multi-threaded, use of fork() may lead to deadlocks in the child.
[2025-10-04T13:45:31.374+0000] {standard_task_runner.py:64} INFO - Started process 196 to run task
[2025-10-04T13:45:31.587+0000] {task_command.py:426} INFO - Running <TaskInstance: retail_hourly_etl.source_transaction_lion_parcel manual__2025-10-04T13:45:27.569105+00:00 [running]> on host 2c8cabdd2b0a
[2025-10-04T13:45:31.995+0000] {taskinstance.py:2648} INFO - Exporting env vars: AIRFLOW_CTX_DAG_OWNER='***' AIRFLOW_CTX_DAG_ID='retail_hourly_etl' AIRFLOW_CTX_TASK_ID='source_transaction_lion_parcel' AIRFLOW_CTX_EXECUTION_DATE='2025-10-04T13:45:27.569105+00:00' AIRFLOW_CTX_TRY_NUMBER='1' AIRFLOW_CTX_DAG_RUN_ID='manual__2025-10-04T13:45:27.569105+00:00'
[2025-10-04T13:45:32.000+0000] {taskinstance.py:430} INFO - ::endgroup::
[2025-10-04T13:45:32.172+0000] {subprocess.py:63} INFO - Tmp dir root location: /tmp
[2025-10-04T13:45:32.177+0000] {subprocess.py:75} INFO - Running command: ['/usr/bin/bash', '-c', 'python /opt/***/public/source_transaction_lion_parcel.py || exit 3']
[2025-10-04T13:45:32.212+0000] {subprocess.py:86} INFO - Output:
[2025-10-04T13:45:43.476+0000] {subprocess.py:93} INFO - 2025-10-04 13:45:43,476 - INFO - Database connection established successfully.
[2025-10-04T13:45:43.478+0000] {subprocess.py:93} INFO - 2025-10-04 13:45:43,477 - INFO - Database connection established successfully.
[2025-10-04T13:45:43.528+0000] {subprocess.py:93} INFO - 2025-10-04 13:45:43,528 - ERROR - Script execution failed: (psycopg2.OperationalError) connection to server at "localhost" (::1), port 5432 failed: Connection refused
[2025-10-04T13:45:43.531+0000] {subprocess.py:93} INFO - 	Is the server running on that host and accepting TCP/IP connections?
[2025-10-04T13:45:43.533+0000] {subprocess.py:93} INFO - connection to server at "localhost" (127.0.0.1), port 5432 failed: Connection refused
[2025-10-04T13:45:43.535+0000] {subprocess.py:93} INFO - 	Is the server running on that host and accepting TCP/IP connections?
[2025-10-04T13:45:43.536+0000] {subprocess.py:93} INFO - 
[2025-10-04T13:45:43.538+0000] {subprocess.py:93} INFO - (Background on this error at: https://sqlalche.me/e/14/e3q8)
[2025-10-04T13:45:43.539+0000] {subprocess.py:93} INFO - Traceback (most recent call last):
[2025-10-04T13:45:43.540+0000] {subprocess.py:93} INFO -   File "/home/***/.local/lib/python3.12/site-packages/sqlalchemy/engine/base.py", line 3371, in _wrap_pool_connect
[2025-10-04T13:45:43.541+0000] {subprocess.py:93} INFO -     return fn()
[2025-10-04T13:45:43.543+0000] {subprocess.py:93} INFO -            ^^^^
[2025-10-04T13:45:43.545+0000] {subprocess.py:93} INFO -   File "/home/***/.local/lib/python3.12/site-packages/sqlalchemy/pool/base.py", line 327, in connect
[2025-10-04T13:45:43.547+0000] {subprocess.py:93} INFO -     return _ConnectionFairy._checkout(self)
[2025-10-04T13:45:43.551+0000] {subprocess.py:93} INFO -            ^^^^^^^^^^^^^^^^^^^^^^^^^^^^^^^^
[2025-10-04T13:45:43.552+0000] {subprocess.py:93} INFO -   File "/home/***/.local/lib/python3.12/site-packages/sqlalchemy/pool/base.py", line 894, in _checkout
[2025-10-04T13:45:43.554+0000] {subprocess.py:93} INFO -     fairy = _ConnectionRecord.checkout(pool)
[2025-10-04T13:45:43.555+0000] {subprocess.py:93} INFO -             ^^^^^^^^^^^^^^^^^^^^^^^^^^^^^^^^
[2025-10-04T13:45:43.556+0000] {subprocess.py:93} INFO -   File "/home/***/.local/lib/python3.12/site-packages/sqlalchemy/pool/base.py", line 493, in checkout
[2025-10-04T13:45:43.557+0000] {subprocess.py:93} INFO -     rec = pool._do_get()
[2025-10-04T13:45:43.559+0000] {subprocess.py:93} INFO -           ^^^^^^^^^^^^^^
[2025-10-04T13:45:43.560+0000] {subprocess.py:93} INFO -   File "/home/***/.local/lib/python3.12/site-packages/sqlalchemy/pool/impl.py", line 145, in _do_get
[2025-10-04T13:45:43.561+0000] {subprocess.py:93} INFO -     with util.safe_reraise():
[2025-10-04T13:45:43.564+0000] {subprocess.py:93} INFO -   File "/home/***/.local/lib/python3.12/site-packages/sqlalchemy/util/langhelpers.py", line 70, in __exit__
[2025-10-04T13:45:43.566+0000] {subprocess.py:93} INFO -     compat.raise_(
[2025-10-04T13:45:43.567+0000] {subprocess.py:93} INFO -   File "/home/***/.local/lib/python3.12/site-packages/sqlalchemy/util/compat.py", line 211, in raise_
[2025-10-04T13:45:43.570+0000] {subprocess.py:93} INFO -     raise exception
[2025-10-04T13:45:43.571+0000] {subprocess.py:93} INFO -   File "/home/***/.local/lib/python3.12/site-packages/sqlalchemy/pool/impl.py", line 143, in _do_get
[2025-10-04T13:45:43.573+0000] {subprocess.py:93} INFO -     return self._create_connection()
[2025-10-04T13:45:43.574+0000] {subprocess.py:93} INFO -            ^^^^^^^^^^^^^^^^^^^^^^^^^
[2025-10-04T13:45:43.575+0000] {subprocess.py:93} INFO -   File "/home/***/.local/lib/python3.12/site-packages/sqlalchemy/pool/base.py", line 273, in _create_connection
[2025-10-04T13:45:43.576+0000] {subprocess.py:93} INFO -     return _ConnectionRecord(self)
[2025-10-04T13:45:43.577+0000] {subprocess.py:93} INFO -            ^^^^^^^^^^^^^^^^^^^^^^^
[2025-10-04T13:45:43.579+0000] {subprocess.py:93} INFO -   File "/home/***/.local/lib/python3.12/site-packages/sqlalchemy/pool/base.py", line 388, in __init__
[2025-10-04T13:45:43.583+0000] {subprocess.py:93} INFO -     self.__connect()
[2025-10-04T13:45:43.585+0000] {subprocess.py:93} INFO -   File "/home/***/.local/lib/python3.12/site-packages/sqlalchemy/pool/base.py", line 690, in __connect
[2025-10-04T13:45:43.587+0000] {subprocess.py:93} INFO -     with util.safe_reraise():
[2025-10-04T13:45:43.588+0000] {subprocess.py:93} INFO -   File "/home/***/.local/lib/python3.12/site-packages/sqlalchemy/util/langhelpers.py", line 70, in __exit__
[2025-10-04T13:45:43.589+0000] {subprocess.py:93} INFO -     compat.raise_(
[2025-10-04T13:45:43.590+0000] {subprocess.py:93} INFO -   File "/home/***/.local/lib/python3.12/site-packages/sqlalchemy/util/compat.py", line 211, in raise_
[2025-10-04T13:45:43.592+0000] {subprocess.py:93} INFO -     raise exception
[2025-10-04T13:45:43.593+0000] {subprocess.py:93} INFO -   File "/home/***/.local/lib/python3.12/site-packages/sqlalchemy/pool/base.py", line 686, in __connect
[2025-10-04T13:45:43.594+0000] {subprocess.py:93} INFO -     self.dbapi_connection = connection = pool._invoke_creator(self)
[2025-10-04T13:45:43.595+0000] {subprocess.py:93} INFO -                                          ^^^^^^^^^^^^^^^^^^^^^^^^^^
[2025-10-04T13:45:43.599+0000] {subprocess.py:93} INFO -   File "/home/***/.local/lib/python3.12/site-packages/sqlalchemy/engine/create.py", line 574, in connect
[2025-10-04T13:45:43.601+0000] {subprocess.py:93} INFO -     return dialect.connect(*cargs, **cparams)
[2025-10-04T13:45:43.602+0000] {subprocess.py:93} INFO -            ^^^^^^^^^^^^^^^^^^^^^^^^^^^^^^^^^^
[2025-10-04T13:45:43.603+0000] {subprocess.py:93} INFO -   File "/home/***/.local/lib/python3.12/site-packages/sqlalchemy/engine/default.py", line 598, in connect
[2025-10-04T13:45:43.605+0000] {subprocess.py:93} INFO -     return self.dbapi.connect(*cargs, **cparams)
[2025-10-04T13:45:43.607+0000] {subprocess.py:93} INFO -            ^^^^^^^^^^^^^^^^^^^^^^^^^^^^^^^^^^^^^
[2025-10-04T13:45:43.608+0000] {subprocess.py:93} INFO -   File "/home/***/.local/lib/python3.12/site-packages/psycopg2/__init__.py", line 122, in connect
[2025-10-04T13:45:43.610+0000] {subprocess.py:93} INFO -     conn = _connect(dsn, connection_factory=connection_factory, **kwasync)
[2025-10-04T13:45:43.611+0000] {subprocess.py:93} INFO -            ^^^^^^^^^^^^^^^^^^^^^^^^^^^^^^^^^^^^^^^^^^^^^^^^^^^^^^^^^^^^^^^
[2025-10-04T13:45:43.612+0000] {subprocess.py:93} INFO - psycopg2.OperationalError: connection to server at "localhost" (::1), port 5432 failed: Connection refused
[2025-10-04T13:45:43.614+0000] {subprocess.py:93} INFO - 	Is the server running on that host and accepting TCP/IP connections?
[2025-10-04T13:45:43.617+0000] {subprocess.py:93} INFO - connection to server at "localhost" (127.0.0.1), port 5432 failed: Connection refused
[2025-10-04T13:45:43.619+0000] {subprocess.py:93} INFO - 	Is the server running on that host and accepting TCP/IP connections?
[2025-10-04T13:45:43.620+0000] {subprocess.py:93} INFO - 
[2025-10-04T13:45:43.621+0000] {subprocess.py:93} INFO - 
[2025-10-04T13:45:43.623+0000] {subprocess.py:93} INFO - The above exception was the direct cause of the following exception:
[2025-10-04T13:45:43.624+0000] {subprocess.py:93} INFO - 
[2025-10-04T13:45:43.625+0000] {subprocess.py:93} INFO - Traceback (most recent call last):
[2025-10-04T13:45:43.627+0000] {subprocess.py:93} INFO -   File "/opt/***/public/source_transaction_lion_parcel.py", line 102, in <module>
[2025-10-04T13:45:43.629+0000] {subprocess.py:93} INFO -     main()
[2025-10-04T13:45:43.630+0000] {subprocess.py:93} INFO -   File "/opt/***/public/source_transaction_lion_parcel.py", line 78, in main
[2025-10-04T13:45:43.633+0000] {subprocess.py:93} INFO -     dfextract = extract(mssql_sferps_engine)
[2025-10-04T13:45:43.634+0000] {subprocess.py:93} INFO -                 ^^^^^^^^^^^^^^^^^^^^^^^^^^^^
[2025-10-04T13:45:43.635+0000] {subprocess.py:93} INFO -   File "/opt/***/public/source_transaction_lion_parcel.py", line 43, in extract
[2025-10-04T13:45:43.637+0000] {subprocess.py:93} INFO -     dfsource = pd.read_sql(sql, con=engine)
[2025-10-04T13:45:43.638+0000] {subprocess.py:93} INFO -                ^^^^^^^^^^^^^^^^^^^^^^^^^^^^
[2025-10-04T13:45:43.639+0000] {subprocess.py:93} INFO -   File "/home/***/.local/lib/python3.12/site-packages/pandas/io/sql.py", line 652, in read_sql
[2025-10-04T13:45:43.640+0000] {subprocess.py:93} INFO -     with pandasSQL_builder(con) as pandas_sql:
[2025-10-04T13:45:43.641+0000] {subprocess.py:93} INFO -          ^^^^^^^^^^^^^^^^^^^^^^
[2025-10-04T13:45:43.643+0000] {subprocess.py:93} INFO -   File "/home/***/.local/lib/python3.12/site-packages/pandas/io/sql.py", line 851, in pandasSQL_builder
[2025-10-04T13:45:43.644+0000] {subprocess.py:93} INFO -     return SQLDatabase(con, schema, need_transaction)
[2025-10-04T13:45:43.645+0000] {subprocess.py:93} INFO -            ^^^^^^^^^^^^^^^^^^^^^^^^^^^^^^^^^^^^^^^^^^
[2025-10-04T13:45:43.646+0000] {subprocess.py:93} INFO -   File "/home/***/.local/lib/python3.12/site-packages/pandas/io/sql.py", line 1576, in __init__
[2025-10-04T13:45:43.648+0000] {subprocess.py:93} INFO -     con = self.exit_stack.enter_context(con.connect())
[2025-10-04T13:45:43.649+0000] {subprocess.py:93} INFO -                                         ^^^^^^^^^^^^^
[2025-10-04T13:45:43.650+0000] {subprocess.py:93} INFO -   File "/home/***/.local/lib/python3.12/site-packages/sqlalchemy/engine/base.py", line 3325, in connect
[2025-10-04T13:45:43.652+0000] {subprocess.py:93} INFO -     return self._connection_cls(self, close_with_result=close_with_result)
[2025-10-04T13:45:43.654+0000] {subprocess.py:93} INFO -            ^^^^^^^^^^^^^^^^^^^^^^^^^^^^^^^^^^^^^^^^^^^^^^^^^^^^^^^^^^^^^^^
[2025-10-04T13:45:43.656+0000] {subprocess.py:93} INFO -   File "/home/***/.local/lib/python3.12/site-packages/sqlalchemy/engine/base.py", line 96, in __init__
[2025-10-04T13:45:43.659+0000] {subprocess.py:93} INFO -     else engine.raw_connection()
[2025-10-04T13:45:43.661+0000] {subprocess.py:93} INFO -          ^^^^^^^^^^^^^^^^^^^^^^^
[2025-10-04T13:45:43.662+0000] {subprocess.py:93} INFO -   File "/home/***/.local/lib/python3.12/site-packages/sqlalchemy/engine/base.py", line 3404, in raw_connection
[2025-10-04T13:45:43.664+0000] {subprocess.py:93} INFO -     return self._wrap_pool_connect(self.pool.connect, _connection)
[2025-10-04T13:45:43.665+0000] {subprocess.py:93} INFO -            ^^^^^^^^^^^^^^^^^^^^^^^^^^^^^^^^^^^^^^^^^^^^^^^^^^^^^^^
[2025-10-04T13:45:43.667+0000] {subprocess.py:93} INFO -   File "/home/***/.local/lib/python3.12/site-packages/sqlalchemy/engine/base.py", line 3374, in _wrap_pool_connect
[2025-10-04T13:45:43.669+0000] {subprocess.py:93} INFO -     Connection._handle_dbapi_exception_noconnection(
[2025-10-04T13:45:43.670+0000] {subprocess.py:93} INFO -   File "/home/***/.local/lib/python3.12/site-packages/sqlalchemy/engine/base.py", line 2208, in _handle_dbapi_exception_noconnection
[2025-10-04T13:45:43.671+0000] {subprocess.py:93} INFO -     util.raise_(
[2025-10-04T13:45:43.673+0000] {subprocess.py:93} INFO -   File "/home/***/.local/lib/python3.12/site-packages/sqlalchemy/util/compat.py", line 211, in raise_
[2025-10-04T13:45:43.674+0000] {subprocess.py:93} INFO -     raise exception
[2025-10-04T13:45:43.676+0000] {subprocess.py:93} INFO -   File "/home/***/.local/lib/python3.12/site-packages/sqlalchemy/engine/base.py", line 3371, in _wrap_pool_connect
[2025-10-04T13:45:43.677+0000] {subprocess.py:93} INFO -     return fn()
[2025-10-04T13:45:43.678+0000] {subprocess.py:93} INFO -            ^^^^
[2025-10-04T13:45:43.679+0000] {subprocess.py:93} INFO -   File "/home/***/.local/lib/python3.12/site-packages/sqlalchemy/pool/base.py", line 327, in connect
[2025-10-04T13:45:43.681+0000] {subprocess.py:93} INFO -     return _ConnectionFairy._checkout(self)
[2025-10-04T13:45:43.683+0000] {subprocess.py:93} INFO -            ^^^^^^^^^^^^^^^^^^^^^^^^^^^^^^^^
[2025-10-04T13:45:43.684+0000] {subprocess.py:93} INFO -   File "/home/***/.local/lib/python3.12/site-packages/sqlalchemy/pool/base.py", line 894, in _checkout
[2025-10-04T13:45:43.687+0000] {subprocess.py:93} INFO -     fairy = _ConnectionRecord.checkout(pool)
[2025-10-04T13:45:43.688+0000] {subprocess.py:93} INFO -             ^^^^^^^^^^^^^^^^^^^^^^^^^^^^^^^^
[2025-10-04T13:45:43.689+0000] {subprocess.py:93} INFO -   File "/home/***/.local/lib/python3.12/site-packages/sqlalchemy/pool/base.py", line 493, in checkout
[2025-10-04T13:45:43.690+0000] {subprocess.py:93} INFO -     rec = pool._do_get()
[2025-10-04T13:45:43.691+0000] {subprocess.py:93} INFO -           ^^^^^^^^^^^^^^
[2025-10-04T13:45:43.692+0000] {subprocess.py:93} INFO -   File "/home/***/.local/lib/python3.12/site-packages/sqlalchemy/pool/impl.py", line 145, in _do_get
[2025-10-04T13:45:43.694+0000] {subprocess.py:93} INFO -     with util.safe_reraise():
[2025-10-04T13:45:43.695+0000] {subprocess.py:93} INFO -   File "/home/***/.local/lib/python3.12/site-packages/sqlalchemy/util/langhelpers.py", line 70, in __exit__
[2025-10-04T13:45:43.696+0000] {subprocess.py:93} INFO -     compat.raise_(
[2025-10-04T13:45:43.697+0000] {subprocess.py:93} INFO -   File "/home/***/.local/lib/python3.12/site-packages/sqlalchemy/util/compat.py", line 211, in raise_
[2025-10-04T13:45:43.699+0000] {subprocess.py:93} INFO -     raise exception
[2025-10-04T13:45:43.700+0000] {subprocess.py:93} INFO -   File "/home/***/.local/lib/python3.12/site-packages/sqlalchemy/pool/impl.py", line 143, in _do_get
[2025-10-04T13:45:43.702+0000] {subprocess.py:93} INFO -     return self._create_connection()
[2025-10-04T13:45:43.703+0000] {subprocess.py:93} INFO -            ^^^^^^^^^^^^^^^^^^^^^^^^^
[2025-10-04T13:45:43.705+0000] {subprocess.py:93} INFO -   File "/home/***/.local/lib/python3.12/site-packages/sqlalchemy/pool/base.py", line 273, in _create_connection
[2025-10-04T13:45:43.706+0000] {subprocess.py:93} INFO -     return _ConnectionRecord(self)
[2025-10-04T13:45:43.708+0000] {subprocess.py:93} INFO -            ^^^^^^^^^^^^^^^^^^^^^^^
[2025-10-04T13:45:43.709+0000] {subprocess.py:93} INFO -   File "/home/***/.local/lib/python3.12/site-packages/sqlalchemy/pool/base.py", line 388, in __init__
[2025-10-04T13:45:43.711+0000] {subprocess.py:93} INFO -     self.__connect()
[2025-10-04T13:45:43.713+0000] {subprocess.py:93} INFO -   File "/home/***/.local/lib/python3.12/site-packages/sqlalchemy/pool/base.py", line 690, in __connect
[2025-10-04T13:45:43.714+0000] {subprocess.py:93} INFO -     with util.safe_reraise():
[2025-10-04T13:45:43.716+0000] {subprocess.py:93} INFO -   File "/home/***/.local/lib/python3.12/site-packages/sqlalchemy/util/langhelpers.py", line 70, in __exit__
[2025-10-04T13:45:43.717+0000] {subprocess.py:93} INFO -     compat.raise_(
[2025-10-04T13:45:43.718+0000] {subprocess.py:93} INFO -   File "/home/***/.local/lib/python3.12/site-packages/sqlalchemy/util/compat.py", line 211, in raise_
[2025-10-04T13:45:43.720+0000] {subprocess.py:93} INFO -     raise exception
[2025-10-04T13:45:43.722+0000] {subprocess.py:93} INFO -   File "/home/***/.local/lib/python3.12/site-packages/sqlalchemy/pool/base.py", line 686, in __connect
[2025-10-04T13:45:43.723+0000] {subprocess.py:93} INFO -     self.dbapi_connection = connection = pool._invoke_creator(self)
[2025-10-04T13:45:43.724+0000] {subprocess.py:93} INFO -                                          ^^^^^^^^^^^^^^^^^^^^^^^^^^
[2025-10-04T13:45:43.726+0000] {subprocess.py:93} INFO -   File "/home/***/.local/lib/python3.12/site-packages/sqlalchemy/engine/create.py", line 574, in connect
[2025-10-04T13:45:43.727+0000] {subprocess.py:93} INFO -     return dialect.connect(*cargs, **cparams)
[2025-10-04T13:45:43.728+0000] {subprocess.py:93} INFO -            ^^^^^^^^^^^^^^^^^^^^^^^^^^^^^^^^^^
[2025-10-04T13:45:43.729+0000] {subprocess.py:93} INFO -   File "/home/***/.local/lib/python3.12/site-packages/sqlalchemy/engine/default.py", line 598, in connect
[2025-10-04T13:45:43.730+0000] {subprocess.py:93} INFO -     return self.dbapi.connect(*cargs, **cparams)
[2025-10-04T13:45:43.732+0000] {subprocess.py:93} INFO -            ^^^^^^^^^^^^^^^^^^^^^^^^^^^^^^^^^^^^^
[2025-10-04T13:45:43.733+0000] {subprocess.py:93} INFO -   File "/home/***/.local/lib/python3.12/site-packages/psycopg2/__init__.py", line 122, in connect
[2025-10-04T13:45:43.734+0000] {subprocess.py:93} INFO -     conn = _connect(dsn, connection_factory=connection_factory, **kwasync)
[2025-10-04T13:45:43.736+0000] {subprocess.py:93} INFO -            ^^^^^^^^^^^^^^^^^^^^^^^^^^^^^^^^^^^^^^^^^^^^^^^^^^^^^^^^^^^^^^^
[2025-10-04T13:45:43.737+0000] {subprocess.py:93} INFO - sqlalchemy.exc.OperationalError: (psycopg2.OperationalError) connection to server at "localhost" (::1), port 5432 failed: Connection refused
[2025-10-04T13:45:43.739+0000] {subprocess.py:93} INFO - 	Is the server running on that host and accepting TCP/IP connections?
[2025-10-04T13:45:43.740+0000] {subprocess.py:93} INFO - connection to server at "localhost" (127.0.0.1), port 5432 failed: Connection refused
[2025-10-04T13:45:43.740+0000] {subprocess.py:93} INFO - 	Is the server running on that host and accepting TCP/IP connections?
[2025-10-04T13:45:43.741+0000] {subprocess.py:93} INFO - 
[2025-10-04T13:45:43.742+0000] {subprocess.py:93} INFO - (Background on this error at: https://sqlalche.me/e/14/e3q8)
[2025-10-04T13:45:44.002+0000] {subprocess.py:97} INFO - Command exited with return code 3
[2025-10-04T13:45:44.009+0000] {taskinstance.py:441} INFO - ::group::Post task execution logs
[2025-10-04T13:45:44.100+0000] {taskinstance.py:2905} ERROR - Task failed with exception
Traceback (most recent call last):
  File "/home/airflow/.local/lib/python3.12/site-packages/airflow/models/taskinstance.py", line 465, in _execute_task
    result = _execute_callable(context=context, **execute_callable_kwargs)
             ^^^^^^^^^^^^^^^^^^^^^^^^^^^^^^^^^^^^^^^^^^^^^^^^^^^^^^^^^^^^^
  File "/home/airflow/.local/lib/python3.12/site-packages/airflow/models/taskinstance.py", line 432, in _execute_callable
    return execute_callable(context=context, **execute_callable_kwargs)
           ^^^^^^^^^^^^^^^^^^^^^^^^^^^^^^^^^^^^^^^^^^^^^^^^^^^^^^^^^^^^
  File "/home/airflow/.local/lib/python3.12/site-packages/airflow/models/baseoperator.py", line 401, in wrapper
    return func(self, *args, **kwargs)
           ^^^^^^^^^^^^^^^^^^^^^^^^^^^
  File "/home/airflow/.local/lib/python3.12/site-packages/airflow/operators/bash.py", line 243, in execute
    raise AirflowException(
airflow.exceptions.AirflowException: Bash command failed. The command returned a non-zero exit code 3.
[2025-10-04T13:45:44.144+0000] {taskinstance.py:1206} INFO - Marking task as FAILED. dag_id=retail_hourly_etl, task_id=source_transaction_lion_parcel, run_id=manual__2025-10-04T13:45:27.569105+00:00, execution_date=20251004T134527, start_date=20251004T134531, end_date=20251004T134544
[2025-10-04T13:45:44.205+0000] {standard_task_runner.py:110} ERROR - Failed to execute job 14 for task source_transaction_lion_parcel (Bash command failed. The command returned a non-zero exit code 3.; 196)
[2025-10-04T13:45:44.263+0000] {local_task_job_runner.py:243} INFO - Task exited with return code 1
[2025-10-04T13:45:44.345+0000] {taskinstance.py:3503} INFO - 0 downstream tasks scheduled from follow-on schedule check
[2025-10-04T13:45:44.355+0000] {local_task_job_runner.py:222} INFO - ::endgroup::
