[2025-10-05T05:20:26.121+0000] {local_task_job_runner.py:120} INFO - ::group::Pre task execution logs
[2025-10-05T05:20:26.893+0000] {taskinstance.py:2076} INFO - Dependencies all met for dep_context=non-requeueable deps ti=<TaskInstance: retail_hourly_etl.retail_transactions_scd manual__2025-10-05T05:18:04.339657+00:00 [queued]>
[2025-10-05T05:20:26.949+0000] {taskinstance.py:2076} INFO - Dependencies all met for dep_context=requeueable deps ti=<TaskInstance: retail_hourly_etl.retail_transactions_scd manual__2025-10-05T05:18:04.339657+00:00 [queued]>
[2025-10-05T05:20:26.951+0000] {taskinstance.py:2306} INFO - Starting attempt 2 of 2
[2025-10-05T05:20:27.024+0000] {taskinstance.py:2330} INFO - Executing <Task(BashOperator): retail_transactions_scd> on 2025-10-05 05:18:04.339657+00:00
[2025-10-05T05:20:27.054+0000] {standard_task_runner.py:90} INFO - Running: ['***', 'tasks', 'run', 'retail_hourly_etl', 'retail_transactions_scd', 'manual__2025-10-05T05:18:04.339657+00:00', '--job-id', '55', '--raw', '--subdir', 'DAGS_FOLDER/retail_hourly_etl.py', '--cfg-path', '/tmp/tmpapcds66q']
[2025-10-05T05:20:27.072+0000] {standard_task_runner.py:91} INFO - Job 55: Subtask retail_transactions_scd
[2025-10-05T05:20:27.075+0000] {logging_mixin.py:188} WARNING - /home/***/.local/lib/python3.12/site-packages/***/task/task_runner/standard_task_runner.py:62 DeprecationWarning: This process (pid=470) is multi-threaded, use of fork() may lead to deadlocks in the child.
[2025-10-05T05:20:27.077+0000] {standard_task_runner.py:64} INFO - Started process 475 to run task
[2025-10-05T05:20:27.336+0000] {task_command.py:426} INFO - Running <TaskInstance: retail_hourly_etl.retail_transactions_scd manual__2025-10-05T05:18:04.339657+00:00 [running]> on host 4be1e35054da
[2025-10-05T05:20:28.614+0000] {taskinstance.py:2648} INFO - Exporting env vars: AIRFLOW_CTX_DAG_OWNER='***' AIRFLOW_CTX_DAG_ID='retail_hourly_etl' AIRFLOW_CTX_TASK_ID='retail_transactions_scd' AIRFLOW_CTX_EXECUTION_DATE='2025-10-05T05:18:04.339657+00:00' AIRFLOW_CTX_TRY_NUMBER='2' AIRFLOW_CTX_DAG_RUN_ID='manual__2025-10-05T05:18:04.339657+00:00'
[2025-10-05T05:20:28.622+0000] {taskinstance.py:430} INFO - ::endgroup::
[2025-10-05T05:20:29.153+0000] {subprocess.py:63} INFO - Tmp dir root location: /tmp
[2025-10-05T05:20:29.229+0000] {subprocess.py:75} INFO - Running command: ['/usr/bin/bash', '-c', 'python /opt/***/public/retail_transactions_scd.py || exit 3']
[2025-10-05T05:20:29.711+0000] {subprocess.py:86} INFO - Output:
[2025-10-05T05:21:12.255+0000] {subprocess.py:93} INFO - 2025-10-05 05:21:12,227 - INFO - Running DBT command: run --select tag:retail_transactions_scd --target prod --project-dir /opt/***/dbt --profiles-dir /opt/***/dbt
[2025-10-05T05:21:12.686+0000] {subprocess.py:93} INFO - [0m05:21:12  Running with dbt=1.8.9
[2025-10-05T05:21:15.144+0000] {subprocess.py:93} INFO - [0m05:21:15  Registered adapter: postgres=1.8.2
[2025-10-05T05:21:17.590+0000] {subprocess.py:93} INFO - [0m05:21:17  [[33mWARNING[0m]: Configuration paths exist in your dbt_project.yml file which do not apply to any resources.
[2025-10-05T05:21:17.593+0000] {subprocess.py:93} INFO - There are 1 unused configuration paths:
[2025-10-05T05:21:17.601+0000] {subprocess.py:93} INFO - - models.lionparcel_dwh.staging
[2025-10-05T05:21:18.722+0000] {subprocess.py:93} INFO - [0m05:21:18  Found 3 models, 1 source, 433 macros
[2025-10-05T05:21:18.745+0000] {subprocess.py:93} INFO - [0m05:21:18
[2025-10-05T05:21:21.292+0000] {subprocess.py:93} INFO - [0m05:21:21  Concurrency: 4 threads (target='prod')
[2025-10-05T05:21:21.299+0000] {subprocess.py:93} INFO - [0m05:21:21
[2025-10-05T05:21:21.367+0000] {subprocess.py:93} INFO - [0m05:21:21  1 of 1 START sql incremental model public.retail_transactions_scd .............. [RUN]
[2025-10-05T05:21:22.440+0000] {subprocess.py:93} INFO - [0m05:21:22  1 of 1 ERROR creating sql incremental model public.retail_transactions_scd ..... [[31mERROR[0m in 1.06s]
[2025-10-05T05:21:22.642+0000] {subprocess.py:93} INFO - [0m05:21:22
[2025-10-05T05:21:22.654+0000] {subprocess.py:93} INFO - [0m05:21:22  Finished running 1 incremental model in 0 hours 0 minutes and 3.89 seconds (3.89s).
[2025-10-05T05:21:22.884+0000] {subprocess.py:93} INFO - [0m05:21:22
[2025-10-05T05:21:22.892+0000] {subprocess.py:93} INFO - [0m05:21:22  [31mCompleted with 1 error and 0 warnings:[0m
[2025-10-05T05:21:22.906+0000] {subprocess.py:93} INFO - [0m05:21:22
[2025-10-05T05:21:22.920+0000] {subprocess.py:93} INFO - [0m05:21:22    Database Error in model retail_transactions_scd (models/marts/retail_transactions_scd.sql)
[2025-10-05T05:21:22.921+0000] {subprocess.py:93} INFO -   nilai kunci ganda melanggar batasan unik Â« pk_retail_transactions_scd Â»
[2025-10-05T05:21:22.923+0000] {subprocess.py:93} INFO -   DETAIL:  Kunci Â« (id, valid_from)=(1004, 2025-01-11 08:00:00+07) Â» sudah ada.
[2025-10-05T05:21:22.928+0000] {subprocess.py:93} INFO -   compiled code at target/run/lionparcel_dwh/models/marts/retail_transactions_scd.sql
[2025-10-05T05:21:22.931+0000] {subprocess.py:93} INFO - [0m05:21:22
[2025-10-05T05:21:22.936+0000] {subprocess.py:93} INFO - [0m05:21:22  Done. PASS=0 WARN=0 ERROR=1 SKIP=0 TOTAL=1
[2025-10-05T05:21:26.053+0000] {subprocess.py:97} INFO - Command exited with return code 3
[2025-10-05T05:21:26.073+0000] {taskinstance.py:441} INFO - ::group::Post task execution logs
[2025-10-05T05:21:26.358+0000] {taskinstance.py:2905} ERROR - Task failed with exception
Traceback (most recent call last):
  File "/home/airflow/.local/lib/python3.12/site-packages/airflow/models/taskinstance.py", line 465, in _execute_task
    result = _execute_callable(context=context, **execute_callable_kwargs)
             ^^^^^^^^^^^^^^^^^^^^^^^^^^^^^^^^^^^^^^^^^^^^^^^^^^^^^^^^^^^^^
  File "/home/airflow/.local/lib/python3.12/site-packages/airflow/models/taskinstance.py", line 432, in _execute_callable
    return execute_callable(context=context, **execute_callable_kwargs)
           ^^^^^^^^^^^^^^^^^^^^^^^^^^^^^^^^^^^^^^^^^^^^^^^^^^^^^^^^^^^^
  File "/home/airflow/.local/lib/python3.12/site-packages/airflow/models/baseoperator.py", line 401, in wrapper
    return func(self, *args, **kwargs)
           ^^^^^^^^^^^^^^^^^^^^^^^^^^^
  File "/home/airflow/.local/lib/python3.12/site-packages/airflow/operators/bash.py", line 243, in execute
    raise AirflowException(
airflow.exceptions.AirflowException: Bash command failed. The command returned a non-zero exit code 3.
[2025-10-05T05:21:26.465+0000] {taskinstance.py:1206} INFO - Marking task as FAILED. dag_id=retail_hourly_etl, task_id=retail_transactions_scd, run_id=manual__2025-10-05T05:18:04.339657+00:00, execution_date=20251005T051804, start_date=20251005T052026, end_date=20251005T052126
[2025-10-05T05:21:26.727+0000] {standard_task_runner.py:110} ERROR - Failed to execute job 55 for task retail_transactions_scd (Bash command failed. The command returned a non-zero exit code 3.; 475)
[2025-10-05T05:21:26.876+0000] {local_task_job_runner.py:243} INFO - Task exited with return code 1
[2025-10-05T05:21:27.233+0000] {taskinstance.py:3503} INFO - 0 downstream tasks scheduled from follow-on schedule check
[2025-10-05T05:21:27.240+0000] {local_task_job_runner.py:222} INFO - ::endgroup::
