[2025-10-05T05:18:27.304+0000] {local_task_job_runner.py:120} INFO - ::group::Pre task execution logs
[2025-10-05T05:18:27.561+0000] {taskinstance.py:2076} INFO - Dependencies all met for dep_context=non-requeueable deps ti=<TaskInstance: retail_hourly_etl.retail_transactions_scd manual__2025-10-05T05:18:04.339657+00:00 [queued]>
[2025-10-05T05:18:27.602+0000] {taskinstance.py:2076} INFO - Dependencies all met for dep_context=requeueable deps ti=<TaskInstance: retail_hourly_etl.retail_transactions_scd manual__2025-10-05T05:18:04.339657+00:00 [queued]>
[2025-10-05T05:18:27.604+0000] {taskinstance.py:2306} INFO - Starting attempt 1 of 1
[2025-10-05T05:18:27.649+0000] {taskinstance.py:2330} INFO - Executing <Task(BashOperator): retail_transactions_scd> on 2025-10-05 05:18:04.339657+00:00
[2025-10-05T05:18:27.681+0000] {standard_task_runner.py:90} INFO - Running: ['***', 'tasks', 'run', 'retail_hourly_etl', 'retail_transactions_scd', 'manual__2025-10-05T05:18:04.339657+00:00', '--job-id', '54', '--raw', '--subdir', 'DAGS_FOLDER/retail_hourly_etl.py', '--cfg-path', '/tmp/tmpvr2f5gyf']
[2025-10-05T05:18:27.692+0000] {standard_task_runner.py:91} INFO - Job 54: Subtask retail_transactions_scd
[2025-10-05T05:18:27.696+0000] {logging_mixin.py:188} WARNING - /home/***/.local/lib/python3.12/site-packages/***/task/task_runner/standard_task_runner.py:62 DeprecationWarning: This process (pid=419) is multi-threaded, use of fork() may lead to deadlocks in the child.
[2025-10-05T05:18:27.700+0000] {standard_task_runner.py:64} INFO - Started process 420 to run task
[2025-10-05T05:18:27.907+0000] {task_command.py:426} INFO - Running <TaskInstance: retail_hourly_etl.retail_transactions_scd manual__2025-10-05T05:18:04.339657+00:00 [running]> on host 4be1e35054da
[2025-10-05T05:18:28.278+0000] {taskinstance.py:2648} INFO - Exporting env vars: AIRFLOW_CTX_DAG_OWNER='***' AIRFLOW_CTX_DAG_ID='retail_hourly_etl' AIRFLOW_CTX_TASK_ID='retail_transactions_scd' AIRFLOW_CTX_EXECUTION_DATE='2025-10-05T05:18:04.339657+00:00' AIRFLOW_CTX_TRY_NUMBER='1' AIRFLOW_CTX_DAG_RUN_ID='manual__2025-10-05T05:18:04.339657+00:00'
[2025-10-05T05:18:28.288+0000] {taskinstance.py:430} INFO - ::endgroup::
[2025-10-05T05:18:28.440+0000] {subprocess.py:63} INFO - Tmp dir root location: /tmp
[2025-10-05T05:18:28.456+0000] {subprocess.py:75} INFO - Running command: ['/usr/bin/bash', '-c', 'python /opt/***/public/retail_transactions_scd.py || exit 3']
[2025-10-05T05:18:28.497+0000] {subprocess.py:86} INFO - Output:
[2025-10-05T05:18:39.473+0000] {subprocess.py:93} INFO - 2025-10-05 05:18:39,471 - INFO - Running DBT command: run --select tag:retail_transactions_scd --target prod --project-dir /opt/***/dbt --profiles-dir /opt/***/dbt
[2025-10-05T05:18:39.707+0000] {subprocess.py:93} INFO - [0m05:18:39  Running with dbt=1.8.9
[2025-10-05T05:18:42.349+0000] {subprocess.py:93} INFO - [0m05:18:42  Registered adapter: postgres=1.8.2
[2025-10-05T05:18:44.396+0000] {subprocess.py:93} INFO - [0m05:18:44  [[33mWARNING[0m]: Configuration paths exist in your dbt_project.yml file which do not apply to any resources.
[2025-10-05T05:18:44.398+0000] {subprocess.py:93} INFO - There are 1 unused configuration paths:
[2025-10-05T05:18:44.399+0000] {subprocess.py:93} INFO - - models.lionparcel_dwh.staging
[2025-10-05T05:18:44.946+0000] {subprocess.py:93} INFO - [0m05:18:44  Found 3 models, 1 source, 433 macros
[2025-10-05T05:18:44.971+0000] {subprocess.py:93} INFO - [0m05:18:44
[2025-10-05T05:18:46.228+0000] {subprocess.py:93} INFO - [0m05:18:46  Concurrency: 4 threads (target='prod')
[2025-10-05T05:18:46.233+0000] {subprocess.py:93} INFO - [0m05:18:46
[2025-10-05T05:18:46.300+0000] {subprocess.py:93} INFO - [0m05:18:46  1 of 1 START sql incremental model public.retail_transactions_scd .............. [RUN]
[2025-10-05T05:18:47.149+0000] {subprocess.py:93} INFO - [0m05:18:47  1 of 1 ERROR creating sql incremental model public.retail_transactions_scd ..... [[31mERROR[0m in 0.83s]
[2025-10-05T05:18:47.324+0000] {subprocess.py:93} INFO - [0m05:18:47
[2025-10-05T05:18:47.328+0000] {subprocess.py:93} INFO - [0m05:18:47  Finished running 1 incremental model in 0 hours 0 minutes and 2.34 seconds (2.34s).
[2025-10-05T05:18:47.548+0000] {subprocess.py:93} INFO - [0m05:18:47
[2025-10-05T05:18:47.563+0000] {subprocess.py:93} INFO - [0m05:18:47  [31mCompleted with 1 error and 0 warnings:[0m
[2025-10-05T05:18:47.566+0000] {subprocess.py:93} INFO - [0m05:18:47
[2025-10-05T05:18:47.571+0000] {subprocess.py:93} INFO - [0m05:18:47    Database Error in model retail_transactions_scd (models/marts/retail_transactions_scd.sql)
[2025-10-05T05:18:47.599+0000] {subprocess.py:93} INFO -   nilai kunci ganda melanggar batasan unik Â« pk_retail_transactions_scd Â»
[2025-10-05T05:18:47.610+0000] {subprocess.py:93} INFO -   DETAIL:  Kunci Â« (id, valid_from)=(1004, 2025-01-11 08:00:00+07) Â» sudah ada.
[2025-10-05T05:18:47.612+0000] {subprocess.py:93} INFO -   compiled code at target/run/lionparcel_dwh/models/marts/retail_transactions_scd.sql
[2025-10-05T05:18:47.613+0000] {subprocess.py:93} INFO - [0m05:18:47
[2025-10-05T05:18:47.615+0000] {subprocess.py:93} INFO - [0m05:18:47  Done. PASS=0 WARN=0 ERROR=1 SKIP=0 TOTAL=1
[2025-10-05T05:18:54.513+0000] {subprocess.py:97} INFO - Command exited with return code 3
[2025-10-05T05:18:54.541+0000] {taskinstance.py:441} INFO - ::group::Post task execution logs
[2025-10-05T05:18:54.800+0000] {taskinstance.py:2905} ERROR - Task failed with exception
Traceback (most recent call last):
  File "/home/airflow/.local/lib/python3.12/site-packages/airflow/models/taskinstance.py", line 465, in _execute_task
    result = _execute_callable(context=context, **execute_callable_kwargs)
             ^^^^^^^^^^^^^^^^^^^^^^^^^^^^^^^^^^^^^^^^^^^^^^^^^^^^^^^^^^^^^
  File "/home/airflow/.local/lib/python3.12/site-packages/airflow/models/taskinstance.py", line 432, in _execute_callable
    return execute_callable(context=context, **execute_callable_kwargs)
           ^^^^^^^^^^^^^^^^^^^^^^^^^^^^^^^^^^^^^^^^^^^^^^^^^^^^^^^^^^^^
  File "/home/airflow/.local/lib/python3.12/site-packages/airflow/models/baseoperator.py", line 401, in wrapper
    return func(self, *args, **kwargs)
           ^^^^^^^^^^^^^^^^^^^^^^^^^^^
  File "/home/airflow/.local/lib/python3.12/site-packages/airflow/operators/bash.py", line 243, in execute
    raise AirflowException(
airflow.exceptions.AirflowException: Bash command failed. The command returned a non-zero exit code 3.
[2025-10-05T05:18:54.849+0000] {taskinstance.py:1206} INFO - Marking task as FAILED. dag_id=retail_hourly_etl, task_id=retail_transactions_scd, run_id=manual__2025-10-05T05:18:04.339657+00:00, execution_date=20251005T051804, start_date=20251005T051827, end_date=20251005T051854
[2025-10-05T05:18:54.973+0000] {standard_task_runner.py:110} ERROR - Failed to execute job 54 for task retail_transactions_scd (Bash command failed. The command returned a non-zero exit code 3.; 420)
[2025-10-05T05:18:55.062+0000] {local_task_job_runner.py:243} INFO - Task exited with return code 1
[2025-10-05T05:18:55.251+0000] {taskinstance.py:3503} INFO - 0 downstream tasks scheduled from follow-on schedule check
[2025-10-05T05:18:55.258+0000] {local_task_job_runner.py:222} INFO - ::endgroup::
